<?xml version="1.0"?>
<!-- =================================================================================== -->
<!-- |    This document was autogenerated by xacro from car.xacro                      | -->
<!-- |    EDITING THIS FILE BY HAND IS NOT RECOMMENDED                                 | -->
<!-- =================================================================================== -->
<robot name="Komibot">
  <!-- /////////////////////////////////////////////////////////////////-->
  <!-- Include materials-->
  <material name="Black">
    <color rgba="0.0 0.0 0.0 1.0"/>
  </material>
  <material name="Red">
    <color rgba="1.0 0 0 1.0"/>
  </material>
  <!-- /////////////////////////////////////////////////////-->
  <!-- ///////////////////////////////////////////////////-->
  <!-- ////////////////////////////////////////////////////-->
  <!--transmission block-->
  <!-- //////////////////////////////////////////////////// -->
  <!-- chassis-->
  <link name="chassis">
    <visual>
      <origin rpy="0 0 0" xyz="0 0 0"/>
      <geometry>
        <mesh filename="package://emrebot/meshes/base_link.stl" scale="0.001 0.001 0.001"/>
      </geometry>
    </visual>
    <collision>
      <origin rpy="0 0 0" xyz="0 0 0"/>
      <geometry>
        <mesh filename="package://emrebot/meshes/base_link.stl" scale="0.001 0.001 0.001"/>
      </geometry>
    </collision>
    <inertial>
      <origin rpy="0.2 0 0" xyz="0 0 0.1"/>
      <mass value="14"/>
      <inertia ixx="0.4" ixy="0.0" ixz="0.0" iyy="0.4" iyz="0.0" izz="0.3"/>
    </inertial>
  </link>
  
  <link name="kafa">
    <inertial>
      <origin xyz="0 0 0" rpy="0.0 0.0 0.0"/>
      <mass value="0.0"/>
      <inertia ixx="0.001" ixy="0.0" ixz="0.0" iyy="0.001" iyz="0.0" izz="0.001"/>
    </inertial>
    <visual name="">
      <origin xyz="0 0 0" rpy="0.0 0.0 0.0"/>
      <geometry>
        <box size="0.3 0.1 0.2"/>
      </geometry>
      <material name="">
        <color rgba="1.0 0.0 0.0 1.0"/>
        <texture filename=""/>
      </material>
    </visual>
    <collision>
      <origin xyz="0.30 0.1 0.2" rpy="0.0 0.0 0.0"/>
      <geometry>
        <box size="0.3 0.1 0.2"/>
      </geometry>
    </collision>
  </link>
  
  <joint name="kafa_to_base" type="fixed">
    <origin xyz="0.0 -0.23 1.12" rpy="0.0 0.0 0.0"/>
    <parent link="chassis"/>
    <child link="kafa"/>
  </joint>


  <!-- ///////////////////      Wheels      ///////////////////////   -->
  <link name="l_f_w">
    <visual>
      <origin xyz="0 0 0" rpy="0 0 0"/>
      <geometry>
        <cylinder radius="0.05" length="0.02"/>
      </geometry>
      <material name="Black"/>
    </visual>
    <collision>
      <origin xyz="0 0 0" rpy="0 0 0"/>
      <geometry>
        <cylinder radius="0.05" length="0.02"/>
      </geometry>
    </collision>
    <inertial>
      <mass value="0.15"/>
      <inertia ixx="0.00013166661400000002" ixy="0.0" ixz="0.0" iyy="0.00013166661400000002" iyz="0.0" izz="0.00025000000000000006"/>
    </inertial>
  </link>


  <joint name="l_f_w_j" type="continuous">
    <parent link="chassis"/>
    <child link="l_f_w"/>
    <origin xyz="0.215 0  0.05" rpy="0 1.5707 0"/>
    <axis xyz="0 0 1"/>
    <limit effort="100" velocity="100"/>
    <dynamics damping="0.0" friction="0.0"/>
  </joint>
  


  <link name="r_f_w">
    <visual>
      <origin xyz="0 0 0" rpy="0 0 0"/>
      <geometry>
        <cylinder radius="0.05" length="0.02"/>
      </geometry>
      <material name="Black"/>
    </visual>
    <collision>
      <origin xyz="0 0 0" rpy="0 0 0"/>
      <geometry>
        <cylinder radius="0.05" length="0.02"/>
      </geometry>
    </collision>
    <inertial>
      <mass value="0.15"/>
      <inertia ixx="0.00013166661400000002" ixy="0.0" ixz="0.0" iyy="0.00013166661400000002" iyz="0.0" izz="0.00025000000000000006"/>
    </inertial>
  </link>

  <joint name="r_f_w_j" type="continuous">
    <parent link="chassis"/>
    <child link="r_f_w"/>
    <origin xyz="-0.215 0 0.05" rpy="0 1.5707 0"/>
    <axis xyz="0 0 1"/>
    <limit effort="100" velocity="100"/>
    <dynamics damping="0.0" friction="0.0"/>
  </joint>


  <link name="camera_link">
    <collision>
      <origin rpy="0 0 0" xyz="0 0 0"/>
      <geometry>
        <box size="0.025 0.1 0.025"/>
      </geometry>
    </collision>
    <visual>
      <origin rpy="0 0 0" xyz="0 0 0"/>
      <geometry>
        <box size="0.025 0.1 0.025"/>
      </geometry>
    </visual>
    <inertial>
      <mass value="0.1"/>
      <origin xyz="0 0 0"/>
      <inertia ixx="8.854163125000002e-05" ixy="0.0" ixz="0.0" iyy="1.0416662500000002e-05" iyz="0.0" izz="8.854163125000002e-05"/>
    </inertial>
  </link>
  <joint name="base_to_camera" type="fixed">
    <origin rpy="0 0 -1.5707" xyz="0 -0.29 1.1"/>
    <parent link="chassis"/>
    <child link="camera_link"/>
  </joint>

  
   <link name="laser_frame">
  <visual>
    <geometry>
      <cylinder radius="0.05" length="0.04"/>
    </geometry>
    <material name="Red"/>
  </visual>
  <collision>
    <geometry>
      <cylinder radius="0.05" length="0.04"/>
    </geometry>
  </collision>
  <inertial>
    <mass value="1e-5"/>
    <origin xyz="0 0 0"/>
    <inertia ixx="1e-6" ixy="0" ixz="0" iyy="1e-6" iyz="0" izz="1e-6" />
  </inertial>
</link>

<joint name="laser_joint" type="fixed">
  <parent link="chassis"/>
  <child link="laser_frame"/>
  <origin xyz="0 -0.37 0.05" rpy="0.0 0.0 -1.5707"/>
</joint>



  <!-- //////////////////////////////////////////////////////////////// -->
  <!-- ros_control plugin-->
  <gazebo>
    <plugin filename="libgazebo_ros_diff_drive.so" name="differential_drive_controller">
      <!-- Plugin update rate in Hz -->
      <updateRate>10.0</updateRate>
      <!-- Name of left joint, defaults to `left_joint` -->
      <leftJoint>l_f_w_j</leftJoint>
      <!-- Name of right joint, defaults to `right_joint` -->
      <rightJoint>r_f_w_j</rightJoint>
      <!-- The distance from the center of one wheel to the other, in meters, defaults to 0.34 m -->
      <wheelSeparation>0.42</wheelSeparation>
      <!-- Diameter of the wheels, in meters, defaults to 0.15 m -->
      <wheelDiameter>0.1</wheelDiameter>
      <!-- Wheel acceleration, in rad/s^2, defaults to 0.0 rad/s^2 -->
      <wheelAcceleration>0.0</wheelAcceleration>
      <!-- Maximum torque which the wheels can produce, in Nm, defaults to 5 Nm -->
      <wheelTorque>75</wheelTorque>
      <!-- Topic to receive geometry_msgs/Twist message commands, defaults to `cmd_vel` -->
      <commandTopic>cmd_vel</commandTopic>
      <!-- Topic to publish nav_msgs/Odometry messages, defaults to `odom` -->
      <odometryTopic>odom</odometryTopic>
      <!-- Odometry frame, defaults to `odom` -->
      <odometryFrame>odom</odometryFrame>
      <!-- Robot frame to calculate odometry from, defaults to `chassis` -->
      <robotBaseFrame>chassis</robotBaseFrame>
      <!-- Odometry source, 0 for ENCODER, 1 for WORLD, defaults to WORLD -->
      <odometrySource>1</odometrySource>
      <!-- Set to true to publish transforms for the wheel links, defaults to false -->
      <publishWheelTF>true</publishWheelTF>
      <!-- Set to true to publish transforms for the odometry, defaults to true -->
      <publishOdom>true</publishOdom>
      <!-- Set to true to publish sensor_msgs/JointState on /joint_states for the wheel joints, defaults to false -->
      <publishWheelJointState>true</publishWheelJointState>
      <!-- Set to true to swap right and left wheels, defaults to true -->
      <legacyMode>true</legacyMode>
    </plugin>
  </gazebo>

</robot>